Traceback (most recent call last):
  File "C:\Users\dents\AppData\Local\Packages\PythonSoftwareFoundation.Python.3.11_qbz5n2kfra8p0\LocalCache\local-packages\Python311\site-packages\jupyter_cache\executors\utils.py", line 58, in single_nb_execution
    executenb(
  File "C:\Users\dents\AppData\Local\Packages\PythonSoftwareFoundation.Python.3.11_qbz5n2kfra8p0\LocalCache\local-packages\Python311\site-packages\nbclient\client.py", line 1314, in execute
    return NotebookClient(nb=nb, resources=resources, km=km, **kwargs).execute()
           ^^^^^^^^^^^^^^^^^^^^^^^^^^^^^^^^^^^^^^^^^^^^^^^^^^^^^^^^^^^^^^^^^^^^^
  File "C:\Users\dents\AppData\Local\Packages\PythonSoftwareFoundation.Python.3.11_qbz5n2kfra8p0\LocalCache\local-packages\Python311\site-packages\jupyter_core\utils\__init__.py", line 165, in wrapped
    return loop.run_until_complete(inner)
           ^^^^^^^^^^^^^^^^^^^^^^^^^^^^^^
  File "C:\Program Files\WindowsApps\PythonSoftwareFoundation.Python.3.11_3.11.2544.0_x64__qbz5n2kfra8p0\Lib\asyncio\base_events.py", line 654, in run_until_complete
    return future.result()
           ^^^^^^^^^^^^^^^
  File "C:\Users\dents\AppData\Local\Packages\PythonSoftwareFoundation.Python.3.11_qbz5n2kfra8p0\LocalCache\local-packages\Python311\site-packages\nbclient\client.py", line 709, in async_execute
    await self.async_execute_cell(
  File "C:\Users\dents\AppData\Local\Packages\PythonSoftwareFoundation.Python.3.11_qbz5n2kfra8p0\LocalCache\local-packages\Python311\site-packages\nbclient\client.py", line 1062, in async_execute_cell
    await self._check_raise_for_error(cell, cell_index, exec_reply)
  File "C:\Users\dents\AppData\Local\Packages\PythonSoftwareFoundation.Python.3.11_qbz5n2kfra8p0\LocalCache\local-packages\Python311\site-packages\nbclient\client.py", line 918, in _check_raise_for_error
    raise CellExecutionError.from_cell_and_msg(cell, exec_reply_content)
nbclient.exceptions.CellExecutionError: An error occurred while executing the following cell:
------------------
from jupyterquiz import display_quiz
git_path="./quizzes/"
display_quiz(git_path+"intro_computing_questions.json")
------------------


[1;31m---------------------------------------------------------------------------[0m
[1;31mFileNotFoundError[0m                         Traceback (most recent call last)
Cell [1;32mIn[1], line 3[0m
[0;32m      1[0m [38;5;28;01mfrom[39;00m [38;5;21;01mjupyterquiz[39;00m [38;5;28;01mimport[39;00m display_quiz
[0;32m      2[0m git_path[38;5;241m=[39m[38;5;124m"[39m[38;5;124m./quizzes/[39m[38;5;124m"[39m
[1;32m----> 3[0m [43mdisplay_quiz[49m[43m([49m[43mgit_path[49m[38;5;241;43m+[39;49m[38;5;124;43m"[39;49m[38;5;124;43mintro_computing_questions.json[39;49m[38;5;124;43m"[39;49m[43m)[49m

File [1;32m~\AppData\Local\Packages\PythonSoftwareFoundation.Python.3.11_qbz5n2kfra8p0\LocalCache\local-packages\Python311\site-packages\jupyterquiz\dynamic.py:176[0m, in [0;36mdisplay_quiz[1;34m(ref, num, shuffle_questions, shuffle_answers, preserve_responses, border_radius, question_alignment, max_width, colors)[0m
[0;32m    173[0m [38;5;28;01melse[39;00m:
[0;32m    174[0m     [38;5;66;03m#print("File detected")[39;00m
[0;32m    175[0m     script [38;5;241m+[39m[38;5;241m=[39m [38;5;124mf[39m[38;5;124m"[39m[38;5;124mvar questions[39m[38;5;132;01m{[39;00mdiv_id[38;5;132;01m}[39;00m[38;5;124m=[39m[38;5;124m"[39m
[1;32m--> 176[0m     [38;5;28;01mwith[39;00m [38;5;28mopen[39m(ref) [38;5;28;01mas[39;00m file:
[0;32m    177[0m         [38;5;28;01mfor[39;00m line [38;5;129;01min[39;00m file:
[0;32m    178[0m             script [38;5;241m+[39m[38;5;241m=[39m line

[1;31mFileNotFoundError[0m: [Errno 2] No such file or directory: './quizzes/intro_computing_questions.json'

